....E.......
======================================================================
ERROR: test_login_users (__main__.TestPractica3)
Try to su into the newly created users
----------------------------------------------------------------------
Traceback (most recent call last):
  File "/home/as/adsis/tests_practicas_AS-master/./tests/test_practica3.py", line 180, in test_login_users
    check_call(["bash", "-c", "cat /etc/passwd | grep {}".format(user)])
  File "/usr/lib/python3.9/subprocess.py", line 373, in check_call
    raise CalledProcessError(retcode, cmd)
subprocess.CalledProcessError: Command '['bash', '-c', 'cat /etc/passwd | grep unizar_as_user0']' returned non-zero exit status 1.

----------------------------------------------------------------------
Ran 12 tests in 3.823s

FAILED (errors=1)
